<?xml version="1.0"?>
<robot name="mycar">
    
  <link name="base_footprint">
      <visual>
      <origin xyz="0 0 0.0" rpy="0 0 0"/>
      <geometry>
        <box size="0.00001 0.00001 0.00001"></box>
      </geometry>
    </visual>
  </link>

  <!-- base link -->
  <link name="base_link">
      <visual>
      <origin xyz="0 0 0.0" rpy="0 0 0"/>
      <geometry>
        <!-- <cylinder length="0.12" radius="0.10"/> -->
        <box size="0.3 0.2 0.1"></box>
      </geometry>
      <material name="yellow">
          <color rgba="0.8 0.5 0.0 0.7" /> 
      </material>
    </visual>
  </link>
    
  <!-- laser link -->
  <link name="laser_link1">
      <visual>
      <origin xyz="0 0 0" rpy="0 0 0"/>
      <geometry>
        <cylinder length="0.02" radius="0.02"/>
      </geometry>
      <material name="black">
          <color rgba="1 0.0 0.0 0.8" /> 
      </material>
    </visual>
  </link>

  <!-- laser link -->
  <link name="laser_link2">
      <visual>
      <origin xyz="0 0 0" rpy="0 0 0"/>
      <geometry>
        <cylinder length="0.02" radius="0.02"/>
      </geometry>
      <material name="black">
          <color rgba="1 1.0 0.0 0.8" /> 
      </material>
    </visual>
  </link>


  <joint name="link2footprint" type="fixed">
      <parent link="base_footprint" />
      <child link="base_link" />
      <origin xyz="0 0 0.05" />
  </joint>
    
  <!-- 1 -->
  <joint name="laser_joint1" type="continuous">
      <parent link="base_link" />
      <child link="laser_link1" />
      <origin xyz="0.15 0.1 0.05" />
      <!-- 设置关节旋转 -->
      <axis xyz="0 0 1" />
  </joint>

  <!-- 2 -->
  <joint name="laser_joint2" type="continuous">
      <parent link="base_link" />
      <child link="laser_link2" />
      <origin xyz="-0.15 -0.1 0.05" />
      <!-- 设置关节旋转 -->
      <axis xyz="0 0 1" />
  </joint>


</robot>
